<?xml version="1.0" encoding="utf-8"?>
<!-- This URDF was automatically created by SolidWorks to URDF Exporter! Originally created by Stephen Brawner (brawner@gmail.com) 
     Commit Version: 1.6.0-1-g15f4949  Build Version: 1.6.7594.29634
     For more information, please see http://wiki.ros.org/sw_urdf_exporter -->
<robot
  name="gripper">
  <link name="world"/>
  <joint name="base_joint" type="fixed">
  	<origin xyz= "0 0 1 " rpy="0 3.1416 0"/>
  	<parent link="world"/>
  	<child link="gripper_base_link"/>
  </joint>
  <link
    name="gripper_base_link">
    <inertial>
      <origin
        xyz="0.00070517 -0.00079249 -0.039763"
        rpy="0 0 0" />
      <mass
        value="0.1334" />
      <inertia
        ixx="2.8688E-05"
        ixy="-4.4946E-08"
        ixz="-3.6321E-07"
        iyy="4.8932E-05"
        iyz="-4.0469E-08"
        izz="3.2073E-05" />
    </inertial>
    <visual>
      <origin
        xyz="0 0 0"
        rpy="0 0 0" />
      <geometry>
        <mesh
          filename="package://gripper_description/meshes/gripper_base_link.STL" />
      </geometry>
      <material
        name="">
        <color
          rgba="0.90196 0.92157 0.92157 1" />
      </material>
    </visual>
    <collision>
      <origin
        xyz="0 0 0"
        rpy="0 0 0" />
      <geometry>
        <mesh
          filename="package://gripper_description/meshes/gripper_base_link.STL" />
      </geometry>
    </collision>
  </link>
  <link
    name="left_actuator">
    <inertial>
      <origin
        xyz="0.03452 -2.9837E-16 0.0013795"
        rpy="0 0 0" />
      <mass
        value="0.013052" />
      <inertia
        ixx="1.1549E-06"
        ixy="-3.5645E-22"
        ixz="-3.3818E-21"
        iyy="3.1196E-06"
        iyz="3.4195E-22"
        izz="2.1584E-06" />
    </inertial>
    <visual>
      <origin
        xyz="0 0 0"
        rpy="0 0 0" />
      <geometry>
        <mesh
          filename="package://gripper_description/meshes/left_actuator.STL" />
      </geometry>
      <material
        name="">
        <color
          rgba="1 1 0 1" />
      </material>
    </visual>
    <collision>
      <origin
        xyz="0 0 0"
        rpy="0 0 0" />
      <geometry>
        <mesh
          filename="package://gripper_description/meshes/left_actuator.STL" />
      </geometry>
    </collision>
  </link>
  <joint
    name="left_act_joint"
    type="revolute">
    <origin
      xyz="0.01 0 -0.02"
      rpy="-1.5708 -1.5708 0" />
    <parent
      link="gripper_base_link" />
    <child
      link="left_actuator" />
    <axis
      xyz="0 0 1" />
    <limit
      lower="0"
      upper="1.5708"
      effort="1"
      velocity="1" />
  </joint>
  <link
    name="rocker_left_link">
    <inertial>
      <origin
        xyz="-0.00076233 0.021677 3.747E-16"
        rpy="0 0 0" />
      <mass
        value="0.028086" />
      <inertia
        ixx="1.617E-05"
        ixy="-2.1715E-06"
        ixz="5.0364E-22"
        iyy="2.1438E-06"
        iyz="3.6038E-21"
        izz="1.6459E-05" />
    </inertial>
    <visual>
      <origin
        xyz="0 0 0"
        rpy="0 0 0" />
      <geometry>
        <mesh
          filename="package://gripper_description/meshes/rocker_left_link.STL" />
      </geometry>
      <material
        name="">
        <color
          rgba="0.95 0.25 0.25 1" />
      </material>
    </visual>
    <collision>
      <origin
        xyz="0 0 0"
        rpy="0 0 0" />
      <geometry>
        <mesh
          filename="package://gripper_description/meshes/rocker_left_link.STL" />
      </geometry>
    </collision>
  </link>
  <joint
    name="rocker_left_joint"
    type="revolute">
    <origin
      xyz="0.055 0 0"
      rpy="0 0 -1.5708" />
    <parent
      link="left_actuator" />
    <child
      link="rocker_left_link" />
    <axis
      xyz="0 0 1" />
    <limit
      lower="-3.1415926"
      upper="3.1415926"
      effort="1"
      velocity="1" />
    <mimic
      joint="left_act_joint"
      multiplier="-1"
      offset="0" />
  </joint>
  <link
    name="right_actuator">
    <inertial>
      <origin
        xyz="0.033438 -2.8927E-16 0.0010856"
        rpy="0 0 0" />
      <mass
        value="0.013474" />
      <inertia
        ixx="1.3401E-06"
        ixy="-6.3169E-21"
        ixz="-3.5833E-21"
        iyy="3.3048E-06"
        iyz="1.1622E-21"
        izz="2.1593E-06" />
    </inertial>
    <visual>
      <origin
        xyz="0 0 0"
        rpy="0 0 0" />
      <geometry>
        <mesh
          filename="package://gripper_description/meshes/right_actuator.STL" />
      </geometry>
      <material
        name="">
        <color
          rgba="1 1 0 1" />
      </material>
    </visual>
    <collision>
      <origin
        xyz="0 0 0"
        rpy="0 0 0" />
      <geometry>
        <mesh
          filename="package://gripper_description/meshes/right_actuator.STL" />
      </geometry>
    </collision>
  </link>
  <joint
    name="right_act_joint"
    type="revolute">
    <origin
      xyz="-0.01 0 -0.02"
      rpy="-1.5708 -1.5708 0" />
    <parent
      link="gripper_base_link" />
    <child
      link="right_actuator" />
    <axis
      xyz="0 0 1" />
    <limit
      lower="0"
      upper="-1.5708"
      effort="1"
      velocity="1" />
    <mimic
      joint="left_act_joint"
      multiplier="-1"
      offset="0" />
  </joint>
  <link
    name="rocker_right_link">
    <inertial>
      <origin
        xyz="-0.00076233 -0.021677 -8.3267E-17"
        rpy="0 0 0" />
      <mass
        value="0.028086" />
      <inertia
        ixx="1.617E-05"
        ixy="2.1715E-06"
        ixz="7.6236E-21"
        iyy="2.1438E-06"
        iyz="-5.0363E-20"
        izz="1.6459E-05" />
    </inertial>
    <visual>
      <origin
        xyz="0 0 0"
        rpy="0 0 0" />
      <geometry>
        <mesh
          filename="package://gripper_description/meshes/rocker_right_link.STL" />
      </geometry>
      <material
        name="">
        <color
          rgba="0.95 0.25 0.25 1" />
      </material>
    </visual>
    <collision>
      <origin
        xyz="0 0 0"
        rpy="0 0 0" />
      <geometry>
        <mesh
          filename="package://gripper_description/meshes/rocker_right_link.STL" />
      </geometry>
    </collision>
  </link>
  <joint
    name="rocker_right_joint"
    type="revolute">
    <origin
      xyz="0.055 0 0"
      rpy="0 0 1.5708" />
    <parent
      link="right_actuator" />
    <child
      link="rocker_right_link" />
    <axis
      xyz="0 0 1" />
    <limit
      lower="-3.1415926"
      upper="3.1415926"
      effort="1"
      velocity="1" />
    <mimic
      joint="right_act_joint"
      multiplier="-1"
      offset="0" />
  </joint>
  <link
    name="crank_left_link">
    <inertial>
      <origin
        xyz="0.0275 6.9389E-18 -0.00030296"
        rpy="0 0 0" />
      <mass
        value="0.016384" />
      <inertia
        ixx="2.1456E-06"
        ixy="-3.7323E-22"
        ixz="1.8204E-22"
        iyy="4.1103E-06"
        iyz="4.9406E-25"
        izz="2.0926E-06" />
    </inertial>
    <visual>
      <origin
        xyz="0 0 0"
        rpy="0 0 0" />
      <geometry>
        <mesh
          filename="package://gripper_description/meshes/crank_left_link.STL" />
      </geometry>
      <material
        name="">
        <color
          rgba="1 1 0 1" />
      </material>
    </visual>
    <collision>
      <origin
        xyz="0 0 0"
        rpy="0 0 0" />
      <geometry>
        <mesh
          filename="package://gripper_description/meshes/crank_left_link.STL" />
      </geometry>
    </collision>
  </link>
  <joint
    name="crank_left_joint"
    type="revolute">
    <origin
      xyz="0.022 0 -0.035"
      rpy="1.5708 -1.5708 0" />
    <parent
      link="gripper_base_link" />
    <child
      link="crank_left_link" />
    <axis
      xyz="0 0 -1" />
    <limit
      lower="-3.1415926"
      upper="3.1415926"
      effort="1.0"
      velocity="1.0" />
    <mimic
      joint="left_act_joint"
      multiplier="1"
      offset="0" />
  </joint>
  <link
    name="crank_right_link">
    <inertial>
      <origin
        xyz="0.0275 5.2042E-18 -0.00030296"
        rpy="0 0 0" />
      <mass
        value="0.016384" />
      <inertia
        ixx="2.1456E-06"
        ixy="-1.611E-22"
        ixz="1.8194E-22"
        iyy="4.1103E-06"
        iyz="-9.5995E-26"
        izz="2.0926E-06" />
    </inertial>
    <visual>
      <origin
        xyz="0 0 0"
        rpy="0 0 0" />
      <geometry>
        <mesh
          filename="package://gripper_description/meshes/crank_right_link.STL" />
      </geometry>
      <material
        name="">
        <color
          rgba="1 1 0 1" />
      </material>
    </visual>
    <collision>
      <origin
        xyz="0 0 0"
        rpy="0 0 0" />
      <geometry>
        <mesh
          filename="package://gripper_description/meshes/crank_right_link.STL" />
      </geometry>
    </collision>
  </link>
  <joint
    name="crank_right_joint"
    type="revolute">
    <origin
      xyz="-0.022 0 -0.035"
      rpy="1.5708 -1.5708 0" />
    <parent
      link="gripper_base_link" />
    <child
      link="crank_right_link" />
    <axis
      xyz="0 0 -1" />
    <limit
      lower="-3.1415926"
      upper="3.1415926"
      effort="1"
      velocity="1" />
    <mimic
      joint="left_act_joint"
      multiplier="-1"
      offset="0" />
  </joint>
  <!-- Gazebo elements-->
  
  <gazebo>
		<plugin name="gazebo_ros_control" filename="libgazebo_ros_control.so"/>
		<robotNamespace>/gripper</robotNamespace>
  </gazebo>
  <!-- gazebo references for links-->
  <gazebo reference="left_actuator">
    <kp>10000.0</kp>
    <kd>1000.0</kd>
  	<mu1>0.2</mu1>
    <mu2>0.2</mu2>
    <material>Gazebo/Yellow</material>
  </gazebo>
  <gazebo reference="crank_left_link">
    <kp>10000.0</kp>
    <kd>1000.0</kd>
  	<mu1>0.2</mu1>
    <mu2>0.2</mu2>
    <material>Gazebo/Yellow</material>
  </gazebo>
  <gazebo reference="rocker_left_link">
    <kp>10000.0</kp>
    <kd>1000.0</kd>
  	<mu1>0.2</mu1>
    <mu2>0.2</mu2>
    <material>Gazebo/Red</material>
  </gazebo>
  <gazebo reference="right_actuator">
    <kp>10000.0</kp>
    <kd>1000.0</kd>
  	<mu1>0.2</mu1>
    <mu2>0.2</mu2>
    <material>Gazebo/Yellow</material>
  </gazebo>
  <gazebo reference="crank_right_link">
    <kp>10000.0</kp>
    <kd>1000.0</kd>
  	<mu1>0.2</mu1>
    <mu2>0.2</mu2>
    <material>Gazebo/Yellow</material>
  </gazebo>
  <gazebo reference="rocker_right_link">
    <kp>10000.0</kp>
    <kd>1000.0</kd>
  	<mu1>0.2</mu1>
    <mu2>0.2</mu2>
    <material>Gazebo/Red</material>
  </gazebo>
  
  <transmission name="trans1">
        <type>transmission_interface/SimpleTransmission</type>
        <joint name="left_act_joint">
            <hardwareInterface>hardware_interface/EffortJointInterface</hardwareInterface>
        </joint>
        <actuator name="motor1">
            <hardwareInterface>hardware_interface/EffortJointInterface</hardwareInterface>
            <mechanicalReduction>1</mechanicalReduction>
        </actuator>
  </transmission>
  
  <gazebo>
  	<plugin name="rocker_left_joint_plugin" filename="libroboticsgroup_upatras_gazebo_mimic_joint_plugin.so">
  		<joint> left_act_joint</joint>
  		<mimicJoint>rocker_left_joint</mimicJoint>
  		<multiplier>-1.0</multiplier>
  		<offset>0.0</offset>
  	</plugin>
  </gazebo>
  <gazebo>
  	<plugin name="right_act_joint_plugin" filename="libroboticsgroup_upatras_gazebo_mimic_joint_plugin.so">
  		<joint> left_act_joint</joint>
  		<mimicJoint>right_act_joint</mimicJoint>
  		<multiplier>-1.0</multiplier>
  		<offset>0.0</offset>
  	</plugin>
  </gazebo>
  <gazebo>
  	<plugin name="rocker_right_joint_plugin" filename="libroboticsgroup_upatras_gazebo_mimic_joint_plugin.so">
  		<joint> right_act_joint</joint>
  		<mimicJoint>rocker_right_joint</mimicJoint>
  		<multiplier>-1.0</multiplier>
  		<offset>0.0</offset>
  	</plugin>
  </gazebo>
  <gazebo>
  	<plugin name="crank_left_joint_plugin" filename="libroboticsgroup_upatras_gazebo_mimic_joint_plugin.so">
  		<joint> left_act_joint</joint>
  		<mimicJoint>crank_left_joint</mimicJoint>
  		<multiplier>1.0</multiplier>
  		<offset>0.0</offset>
  	</plugin>
  </gazebo>
  <gazebo>
  	<plugin name="crank_right_joint_plugin" filename="libroboticsgroup_upatras_gazebo_mimic_joint_plugin.so">
  		<joint> left_act_joint</joint>
  		<mimicJoint>crank_right_joint</mimicJoint>
  		<multiplier>-1.0</multiplier>
  		<offset>0.0</offset>
  	</plugin>
  </gazebo>
</robot>
